<?xml version="1.0" ?>
<!-- =================================================================================== -->
<!-- |    This document was autogenerated by xacro from robot.xacro                    | -->
<!-- |    EDITING THIS FILE BY HAND IS NOT RECOMMENDED                                 | -->
<!-- =================================================================================== -->
<robot name="Hound_description" xmlns:xacro="http://www.ros.org/wiki/xacro">
  <material name="black">
    <color rgba="0.0 0.0 0.0 1.0"/>
  </material>
  <material name="blue">
    <color rgba="0.0 0.0 0.8 1.0"/>
  </material>
  <material name="green">
    <color rgba="0.0 0.8 0.0 1.0"/>
  </material>
  <material name="grey">
    <color rgba="0.2 0.2 0.2 1.0"/>
  </material>
  <material name="silver">
    <color rgba="0.913725490196 0.913725490196 0.847058823529 1.0"/>
  </material>
  <material name="orange">
    <color rgba="1.0 0.423529411765 0.0392156862745 1.0"/>
  </material>
  <material name="brown">
    <color rgba="0.870588235294 0.811764705882 0.764705882353 1.0"/>
  </material>
  <material name="red">
    <color rgba="0.8 0.0 0.0 1.0"/>
  </material>
  <material name="white">
    <color rgba="1.0 1.0 1.0 1.0"/>
  </material>

  <link name="trunk">
    <visual>
      <origin rpy="0 0 0" xyz="0 0 0"/>
      <geometry>
        <mesh filename="package://hound_description/meshes/base__.dae" scale="1 1 1"/>
      </geometry>
      <material name="black"/>
    </visual>
    <collision>
      <origin rpy="0 0 0" xyz="0 0 0"/>
      <geometry>
	<!--<box size="0.562 0.335 0.14"/>-->
        <box size="0.562 0.185 0.08"/>
      </geometry>
    </collision>
    <inertial>
      <origin rpy="0 0 0" xyz="0.00013607 0.00001388 0.00185744"/>
      <mass value="17.66173773"/>
      <inertia ixx="0.20856455" ixy="-0.00072126" ixz="-0.00004529" iyy="0.80371419" iyz="0.00001535" izz="0.95938169"/>
    </inertial>
  </link>

  <joint name="FR_roll_joint" type="revolute">
    <origin rpy="0 0 0" xyz="0.349 -0.100 0.000"/>
    <parent link="trunk"/>
    <child link="FR_shoulder"/>
    <axis xyz="1 0 0"/>
    <dynamics rotor_inertia="0.01398664" damping="0" friction="0"/>
    <limit effort="200" lower="-1.48352986419518" upper="1.48352986419518" velocity="16.7"/>
  </joint>

  <link name="FR_shoulder">
    <visual>
      <origin rpy="0 0 0" xyz="0 0 0"/>
      <geometry>
        <mesh filename="package://hound_description/meshes/shoulder_mirror__.dae" scale="1 1 1"/>
      </geometry>
      <material name="grey"/>
    </visual>
    <collision>
      <origin rpy="1.57079632679 0 0" xyz="0 -0.0125 0"/>
      <geometry>
        <cylinder length="0.133" radius="0.0605"/>
      </geometry>
    </collision>
    <inertial>
      <origin rpy="0 0 0" xyz="-0.00426027 -0.01325422 0.00000918"/>
      <mass value="3.96168582"/>
      <inertia ixx="0.00932019" ixy="-0.00003601" ixz="-0.00000533" iyy="0.00773259" iyz="-0.00001700" izz="0.01043512"/>
    </inertial>
  </link>

  <joint name="FR_hip_joint" type="revolute">
    <origin rpy="0 0 0" xyz="0 -0.1135 0"/>
    <parent link="FR_shoulder"/>
    <child link="FR_thigh"/>
    <axis xyz="0 1 0"/>
    <dynamics rotor_inertia="0.05581304" damping="0" friction="0"/>
    <limit effort="200" lower="-6.28318530718" upper="6.28318530718" velocity="16.7"/>
  </joint>

  <link name="FR_thigh">
    <visual>
      <origin rpy="0 0 0" xyz="0 0 0"/>
      <geometry>
        <mesh filename="package://hound_description/meshes/thigh_mirror__.dae" scale="1 1 1"/>
      </geometry>
      <material name="grey"/>
    </visual>
    <collision>
      <origin rpy="0 0 0" xyz="0 0 -0.16395"/>
      <geometry>
        <box size="0.078 0.069 0.3279"/>
      </geometry>
    </collision>
    <inertial>
      <origin rpy="0 0 0" xyz="0.01353461 0.01879181 -0.09638993"/>
      <mass value="1.52408165"/>
      <inertia ixx="0.02365733" ixy="-0.00036775" ixz="-0.00293293" iyy="0.02323490" iyz="0.00261899" izz="0.00318143"/>
    </inertial>
  </link>

  <joint name="FR_knee_joint" type="revolute">
    <origin rpy="0 0 0" xyz="0 0 -0.3279"/>
    <parent link="FR_thigh"/>
    <child link="FR_calf"/>
    <axis xyz="0 1 0"/>
    <dynamics rotor_inertia="0.0561" damping="0" friction="0"/>
    <limit effort="400" lower="-2.7925268" upper="2.7925268" velocity="8.420868347"/>
  </joint>

  <link name="FR_calf">
    <visual>
      <origin rpy="0 0 0" xyz="0 0 0"/>
      <geometry>
        <mesh filename="package://hound_description/meshes/calf__.dae" scale="1 1 1"/>
      </geometry>
      <material name="silver"/>
    </visual>
    <collision>
      <origin rpy="0 0 0" xyz="0 0 -0.175"/>
      <geometry>
        <box size="0.032 0.032 0.35"/>
      </geometry>
    </collision>
    <inertial>
      <origin rpy="0 0 0" xyz="0.00000000 -0.00007139 -0.12613433"/>
      <mass value="0.68173107"/>
      <inertia ixx="0.01354125" ixy="-0.00000000" ixz="-0.00000058" iyy="0.01354008" iyz="-0.00000573" izz="0.00042390"/>
    </inertial>
  </link>

  <joint name="FR_foot_fixed" type="fixed">
    <origin rpy="0 0 0" xyz="0 0 -0.35"/>
    <parent link="FR_calf"/>
    <child link="FR_foot"/>
  </joint>

  <link name="FR_foot">
    <visual>
      <origin rpy="0 0 0" xyz="0 0 0"/>
      <geometry>
        <sphere radius="0.03"/>
      </geometry>
    </visual>
    <collision>
      <origin rpy="0 0 0" xyz="0 0 0"/>
      <geometry>
        <sphere radius="0.03"/>
      </geometry>
    </collision>
  </link>


  <joint name="FL_roll_joint" type="revolute">
    <origin rpy="0 0 0" xyz="0.349 0.100 0.000"/>
    <parent link="trunk"/>
    <child link="FL_shoulder"/>
    <axis xyz="1 0 0"/>
    <dynamics rotor_inertia="0.01398664" damping="0" friction="0"/>
    <limit effort="200" lower="-1.48352986419518" upper="1.48352986419518" velocity="16.7"/>
  </joint>

  <link name="FL_shoulder">
    <visual>
      <origin rpy="0 0 0" xyz="0 0 0"/>
      <geometry>
        <mesh filename="package://hound_description/meshes/shoulder__.dae" scale="1 1 1"/>
      </geometry>
      <material name="grey"/>
    </visual>
    <collision>
      <origin rpy="1.57079632679 0 0" xyz="0 0.0125 0"/>
      <geometry>
        <cylinder length="0.133" radius="0.0605"/>
      </geometry>
    </collision>
    <inertial>
      <origin rpy="0 0 0" xyz="-0.00426027 0.01325422 0.00000918"/>
      <mass value="3.96168582"/>
      <inertia ixx="0.00932019" ixy="0.00003601" ixz="-0.00000533" iyy="0.00773259" iyz="0.00001700" izz="0.01043512"/>
    </inertial>
  </link>

  <joint name="FL_hip_joint" type="revolute">
    <origin rpy="0 0 0" xyz="0 0.1135 0"/>
    <parent link="FL_shoulder"/>
    <child link="FL_thigh"/>
    <axis xyz="0 1 0"/>
    <dynamics rotor_inertia="0.05581304" damping="0" friction="0"/>
    <limit effort="200" lower="-6.28318530718" upper="6.28318530718" velocity="16.7"/>
  </joint>

  <link name="FL_thigh">
    <visual>
      <origin rpy="0 0 0" xyz="0 0 0"/>
      <geometry>
        <mesh filename="package://hound_description/meshes/thigh__.dae" scale="1 1 1"/>
      </geometry>
      <material name="grey"/>
    </visual>
    <collision>
      <origin rpy="0 0 0" xyz="0 0 -0.16395"/>
      <geometry>
        <box size="0.078 0.069 0.3279"/>
      </geometry>
    </collision>
    <inertial>
      <origin rpy="0 0 0" xyz="0.01353461 -0.01879181 -0.09638993"/>
      <mass value="1.52408165"/>
      <inertia ixx="0.02365733" ixy="0.00036775" ixz="-0.00293293" iyy="0.02323490" iyz="-0.00261899" izz="0.00318143"/>
    </inertial>
  </link>

  <joint name="FL_knee_joint" type="revolute">
    <origin rpy="0 0 0" xyz="0 0 -0.3279"/>
    <parent link="FL_thigh"/>
    <child link="FL_calf"/>
    <axis xyz="0 1 0"/>
    <dynamics rotor_inertia="0.0561" damping="0" friction="0"/>
    <limit effort="400" lower="-2.7925268" upper="2.7925268" velocity="8.420868347"/>
  </joint>

  <link name="FL_calf">
    <visual>
      <origin rpy="0 0 0" xyz="0 0 0"/>
      <geometry>
        <mesh filename="package://hound_description/meshes/calf__.dae" scale="1 1 1"/>
      </geometry>
      <material name="silver"/>
    </visual>
    <collision>
      <origin rpy="0 0 0" xyz="0 0 -0.175"/>
      <geometry>
        <box size="0.032 0.032 0.35"/>
      </geometry>
    </collision>
    <inertial>
      <origin rpy="0 0 0" xyz="0.00000000 0.00007139 -0.12613433"/>
      <mass value="0.68173107"/>
      <inertia ixx="0.01354125" ixy="0.00000000" ixz="-0.00000058" iyy="0.01354008" iyz="0.00000573" izz="0.00042390"/>
    </inertial>
  </link>

  <joint name="FL_foot_fixed" type="fixed">
    <origin rpy="0 0 0" xyz="0 0 -0.35"/>
    <parent link="FL_calf"/>
    <child link="FL_foot"/>
  </joint>

  <link name="FL_foot">
    <visual>
      <origin rpy="0 0 0" xyz="0 0 0"/>
      <geometry>
        <sphere radius="0.03"/>
      </geometry>
    </visual>
    <collision>
      <origin rpy="0 0 0" xyz="0 0 0"/>
      <geometry>
        <sphere radius="0.03"/>
      </geometry>
    </collision>
  </link>


  <joint name="RR_roll_joint" type="revolute">
    <origin rpy="0 0 0" xyz="-0.349 -0.100 0.000"/>
    <parent link="trunk"/>
    <child link="RR_shoulder"/>
    <axis xyz="1 0 0"/>
    <dynamics rotor_inertia="0.01398664" damping="0" friction="0"/>
    <limit effort="200" lower="-1.48352986419518" upper="1.48352986419518" velocity="16.7"/>
  </joint>

  <link name="RR_shoulder">
    <visual>
      <origin rpy="0 0 0" xyz="0 0 0"/>
      <geometry>
        <mesh filename="package://hound_description/meshes/shoulder_mirror__.dae" scale="1 1 1"/>
      </geometry>
      <material name="grey"/>
    </visual>
    <collision>
      <origin rpy="1.57079632679 0 0" xyz="0 -0.0125 0"/>
      <geometry>
        <cylinder length="0.133" radius="0.0605"/>
      </geometry>
    </collision>
    <inertial>
      <origin rpy="0 0 0" xyz="-0.00426027 -0.01325422 0.00000918"/>
      <mass value="3.96168582"/>
      <inertia ixx="0.00932019" ixy="-0.00003601" ixz="-0.00000533" iyy="0.00773259" iyz="-0.00001700" izz="0.01043512"/>
    </inertial>
  </link>

  <joint name="RR_hip_joint" type="revolute">
    <origin rpy="0 0 0" xyz="0 -0.1135 0"/>
    <parent link="RR_shoulder"/>
    <child link="RR_thigh"/>
    <axis xyz="0 1 0"/>
    <dynamics rotor_inertia="0.05581304" damping="0" friction="0"/>
    <limit effort="200" lower="-6.28318530718" upper="6.28318530718" velocity="16.7"/>
  </joint>

  <link name="RR_thigh">
    <visual>
      <origin rpy="0 0 0" xyz="0 0 0"/>
      <geometry>
        <mesh filename="package://hound_description/meshes/thigh_mirror__.dae" scale="1 1 1"/>
      </geometry>
      <material name="grey"/>
    </visual>
    <collision>
      <origin rpy="0 0 0" xyz="0 0 -0.16395"/>
      <geometry>
        <box size="0.078 0.069 0.3279"/>
      </geometry>
    </collision>
    <inertial>
      <origin rpy="0 0 0" xyz="0.01353461 0.01879181 -0.09638993"/>
      <mass value="1.52408165"/>
      <inertia ixx="0.02365733" ixy="-0.00036775" ixz="-0.00293293" iyy="0.02323490" iyz="0.00261899" izz="0.00318143"/>
    </inertial>
  </link>

  <joint name="RR_knee_joint" type="revolute">
    <origin rpy="0 0 0" xyz="0 0 -0.3279"/>
    <parent link="RR_thigh"/>
    <child link="RR_calf"/>
    <axis xyz="0 1 0"/>
    <dynamics rotor_inertia="0.0561" damping="0" friction="0"/>
    <limit effort="400" lower="-2.7925268" upper="2.7925268" velocity="8.420868347"/>
  </joint>

  <link name="RR_calf">
    <visual>
      <origin rpy="0 0 0" xyz="0 0 0"/>
      <geometry>
        <mesh filename="package://hound_description/meshes/calf__.dae" scale="1 1 1"/>
      </geometry>
      <material name="silver"/>
    </visual>
    <collision>
      <origin rpy="0 0 0" xyz="0 0 -0.175"/>
      <geometry>
        <box size="0.032 0.032 0.35"/>
      </geometry>
    </collision>
    <inertial>
      <origin rpy="0 0 0" xyz="0.00000000 -0.00007139 -0.12613433"/>
      <mass value="0.68173107"/>
      <inertia ixx="0.01354125" ixy="-0.00000000" ixz="-0.00000058" iyy="0.01354008" iyz="-0.00000573" izz="0.00042390"/>
    </inertial>
  </link>

  <joint name="RR_foot_fixed" type="fixed">
    <origin rpy="0 0 0" xyz="0 0 -0.35"/>
    <parent link="RR_calf"/>
    <child link="RR_foot"/>
  </joint>

  <link name="RR_foot">
    <visual>
      <origin rpy="0 0 0" xyz="0 0 0"/>
      <geometry>
        <sphere radius="0.03"/>
      </geometry>
    </visual>
    <collision>
      <origin rpy="0 0 0" xyz="0 0 0"/>
      <geometry>
        <sphere radius="0.03"/>
      </geometry>
    </collision>
  </link>


  <joint name="RL_roll_joint" type="revolute">
    <origin rpy="0 0 0" xyz="-0.349 0.100 0.000"/>
    <parent link="trunk"/>
    <child link="RL_shoulder"/>
    <axis xyz="1 0 0"/>
    <dynamics rotor_inertia="0.01398664" damping="0" friction="0"/>
    <limit effort="200" lower="-1.48352986419518" upper="1.48352986419518" velocity="16.7"/>
  </joint>

  <link name="RL_shoulder">
    <visual>
      <origin rpy="0 0 0" xyz="0 0 0"/>
      <geometry>
        <mesh filename="package://hound_description/meshes/shoulder__.dae" scale="1 1 1"/>
      </geometry>
      <material name="grey"/>
    </visual>
    <collision>
      <origin rpy="1.57079632679 0 0" xyz="0 0.0125 0"/>
      <geometry>
        <cylinder length="0.133" radius="0.0605"/>
      </geometry>
    </collision>
    <inertial>
      <origin rpy="0 0 0" xyz="-0.00426027 0.01325422 0.00000918"/>
      <mass value="3.96168582"/>
      <inertia ixx="0.00932019" ixy="0.00003601" ixz="-0.00000533" iyy="0.00773259" iyz="0.00001700" izz="0.01043512"/>
    </inertial>
  </link>

  <joint name="RL_hip_joint" type="revolute">
    <origin rpy="0 0 0" xyz="0 0.1135 0"/>
    <parent link="RL_shoulder"/>
    <child link="RL_thigh"/>
    <axis xyz="0 1 0"/>
    <dynamics rotor_inertia="0.05581304" damping="0" friction="0"/>
    <limit effort="200" lower="-6.28318530718" upper="6.28318530718" velocity="16.7"/>
  </joint>

  <link name="RL_thigh">
    <visual>
      <origin rpy="0 0 0" xyz="0 0 0"/>
      <geometry>
        <mesh filename="package://hound_description/meshes/thigh__.dae" scale="1 1 1"/>
      </geometry>
      <material name="grey"/>
    </visual>
    <collision>
      <origin rpy="0 0 0" xyz="0 0 -0.16395"/>
      <geometry>
        <box size="0.078 0.069 0.3279"/>
      </geometry>
    </collision>
    <inertial>
      <origin rpy="0 0 0" xyz="0.01353461 -0.01879181 -0.09638993"/>
      <mass value="1.52408165"/>
      <inertia ixx="0.02365733" ixy="0.00036775" ixz="-0.00293293" iyy="0.02323490" iyz="-0.00261899" izz="0.00318143"/>
    </inertial>
  </link>

  <joint name="RL_knee_joint" type="revolute">
    <origin rpy="0 0 0" xyz="0 0 -0.3279"/>
    <parent link="RL_thigh"/>
    <child link="RL_calf"/>
    <axis xyz="0 1 0"/>
    <dynamics rotor_inertia="0.0561" damping="0" friction="0"/>
    <limit effort="400" lower="-2.7925268" upper="2.7925268" velocity="8.420868347"/>
  </joint>

  <link name="RL_calf">
    <visual>
      <origin rpy="0 0 0" xyz="0 0 0"/>
      <geometry>
        <mesh filename="package://hound_description/meshes/calf__.dae" scale="1 1 1"/>
      </geometry>
      <material name="silver"/>
    </visual>
    <collision>
      <origin rpy="0 0 0" xyz="0 0 -0.175"/>
      <geometry>
        <box size="0.032 0.032 0.35"/>
      </geometry>
    </collision>
    <inertial>
      <origin rpy="0 0 0" xyz="0.00000000 0.00007139 -0.12613433"/>
      <mass value="0.68173107"/>
      <inertia ixx="0.01354125" ixy="0.00000000" ixz="-0.00000058" iyy="0.01354008" iyz="0.00000573" izz="0.00042390"/>
    </inertial>
  </link>

  <joint name="RL_foot_fixed" type="fixed">
    <origin rpy="0 0 0" xyz="0 0 -0.35"/>
    <parent link="RL_calf"/>
    <child link="RL_foot"/>
  </joint>

  <link name="RL_foot">
    <visual>
      <origin rpy="0 0 0" xyz="0 0 0"/>
      <geometry>
        <sphere radius="0.03"/>
      </geometry>
    </visual>
    <collision>
      <origin rpy="0 0 0" xyz="0 0 0"/>
      <geometry>
        <sphere radius="0.03"/>
      </geometry>
    </collision>
  </link>
</robot>
